Workbook

Sheet Январь
A1: Оториноларингологическое отделение за январь 2026
B2: С | C2: 46023 | D2: =IF(C3="","",IF(C3+1>EOMONTH($C$2,0),"",C3+1)) | E2: =IF(D3="","",IF(D3+1>EOMONTH($C$2,0),"",D3+1)) | F2: =IF(E3="","",IF(E3+1>EOMONTH($C$2,0),"",E3+1)) | G2: =IF(F3="","",IF(F3+1>EOMONTH($C$2,0),"",F3+1))
B3: По | C3: =IF(C2="","",MIN(C2+7-WEEKDAY(C2,2),EOMONTH($C$2,0))) | D3: =IF(D2="","",MIN(D2+6,EOMONTH($C$2,0))) | E3: =IF(E2="","",MIN(E2+6,EOMONTH($C$2,0))) | F3: =IF(F2="","",MIN(F2+6,EOMONTH($C$2,0))) | G3: =IF(G2="","",MIN(G2+6,EOMONTH($C$2,0))) | H3: ИТОГ
B4: Аденотомия | E4: 18 | F4: 11 | G4: 5 | H4: =SUM(C4:G4)
B5: Тонзиллотомия | E5: 5 | F5: 4 | G5: 3 | H5: =SUM(C5:G5)
B6: Миринготомия план | H6: =SUM(C6:G6) | S6: ХИРУРГИЧЕСКАЯ РАБОТА ОРГАНИЗАЦИИ (лица старше трудоспособного возраста) 4001
B7: Пластика раковин | E7: 1 | F7: 7 | G7: 6 | H7: =SUM(C7:G7) | L7: Наименование операции | M7: № строки | N7: Число операций, проведенных в стационаре | R7: из гр.3 направлено материалов на морфол. исследование | S7: Число операций, проведенных в стационаре
B8: ПТА | E8: 5 | F8: 1 | G8: 3 | H8: =SUM(C8:G8) | N8: всего | O8: из них - детям 0-17 лет включительно | S8: Всего (из гр.3 т.4000)
B9: Миринготомия экстр | G9: 1 | H9: =SUM(C9:G9) | O9: 0-14 лет включи-тельно | P9: из гр.4 в возрасте до 1 года | Q9: 15-17 лет включи-тельно
B10: Полипотомия | H10: =SUM(C10:G10) | L10: 1 | M10: 2 | N10: 3 | O10: 4 | P10: 5 | Q10: 6 | R10: 28 | S10: 3
B11: Септопластика | E11: 1 | F11: 3 | G11: 3 | H11: =SUM(C11:G11) | L11: операции на органах уха, горла, носа | M11: 5 | N11: =SUM(N12:N13) | O11: =SUM(O12:O13)-Q11 | Q11: =SUM(Q12+Q13) | R11: =SUM(R12+R13+H25) | S11: 2
B12: Гайморотомия | F12: 2 | G12: 1 | H12: =SUM(C12:G12) | L12: из них - на ухе | M12: 5.1 | N12: =SUM(H6+H9+H16+H22+H26+H24+H32) | Q12: 1 | R12: =SUM(H22+H26)
B13: Тозиллэктомия | E13: 3 | F13: 3 | G13: 3 | H13: =SUM(C13:G13) | L13: на миндалинах и аденоидах | M13: 5.2 | N13: =SUM(H4+H5+H8+H13) | O13: =SUM(H4+H5)-Q13 | Q13: 0 | R13: =SUM(H4+H5+H13) | S13: 1
B14: Увулопластика | H14: =SUM(C14:G14) | L14: операции на органах дыхания | M14: 6 | N14: =SUM(H7+H10+H11+H12+H14+H15+H17+H18+H20+H21+H23+H25+H27+H30+H31+H19+H34+H36+H28+H37) | O14: 0 | Q14: 2 | R14: =SUM(H10+H12+H14+H27+H28+H37) | S14: 2
B15: Пластика нёба | H15: =SUM(C15:G15) | L15: из них - на трахее | M15: 6.1 | N15: =SUM(H18) | O15: 0 | R15: 0
B16: Фурункул НСП | F16: 2 | G16: 1 | H16: =SUM(C16:G16) | L16: операции на коже и подкожной клетчатке | M16: 17 | N16: =SUM(H35+H33+H29) | O16: 0 | Q16: 0 | R16: 0
B17: Фурункул носа | E17: 1 | F17: 1 | H17: =SUM(C17:G17) | L17: Операции лицам пенсионного возраста | N17: 0 | O17: 0 | R17: 0
B18: Трахеостомия | F18: 1 | H18: =SUM(C18:G18) | L18: Всего операций | N18: =N16+N14+N11 | O18: =SUM(O11+O14+O16)-Q14 | Q18: =SUM(Q11+Q14+Q16) | R18: =SUM(R11+R14+R16) | S18: =SUM(S11+S14+S16)
B19: Репозиция костей носа | G19: 1 | H19: =SUM(C19:G19)
B20: Флегмона шеи | H20: =SUM(C20:G20) | L20: Эндоскопических всего | N20: =H4+H7+H10+H11+H12+H13+H28+H37
B21: Остановка кров | E21: 1 | G21: 2 | H21: =SUM(C21:G21)
B22: Рубцы мочки уха | G22: 1 | H22: =SUM(C22:G22)
B23: Синехии нос | H23: =SUM(C23:G23)
B24: Антромастоидотомия | H24: =SUM(C24:G24)
B25: Удаление новообр носа | H25: =SUM(C25:G25)
B26: Удаление новообр уха | H26: =SUM(C26:G26)
B27: Удаление новообр глотки | G27: 2 | H27: =SUM(C27:G27)
B28: Удаление новообр гортани | H28: =SUM(C28:G28)
B29: ПХО | H29: =SUM(C29:G29)
B30: Удаление инородного тела | H30: =SUM(C30:G30)
B31: Фронтотомия | H31: =SUM(C31:G31)
B32: Субперостальный абсцесс за ухом | H32: =SUM(C32:G32)
B33: Пластика местными тканями | G33: 1 | H33: =SUM(C33:G33)
B34: Ревизия п/о полости | H34: =SUM(C34:G34)
B35: Наложение вторичных швов | H35: =SUM(C35:G35)
B36: Заглоточный абсцесс | H36: =SUM(C36:G36)
B37: Биопсия гортани | F37: 1 | H37: =SUM(C37:G37)
B40: Всего операций | C40: =SUM(C4:C37) | D40: =SUM(D4:D37) | E40: =SUM(E4:E37) | F40: =SUM(F4:F37) | G40: =SUM(G4:G37) | H40: =SUM(C40:G40)
B41: Экстренно операций | C41: =SUM(C8+C9+C16+C17+C18+C19+C20+C21+C24+C29+C30+C31+C32+C34+C36) | D41: =SUM(D8+D9+D16+D17+D18+D19+D20+D21+D24+D29+D30+D31+D32+D34+D36) | E41: =SUM(E8+E9+E16+E17+E18+E19+E20+E21+E24+E29+E30+E31+E32+E34+E36) | F41: =SUM(F8+F9+F16+F17+F18+F19+F20+F21+F24+F29+F30+F31+F32+F34+F36) | G41: =SUM(G8+G9+G16+G17+G18+G19+G20+G21+G24+G29+G30+G31+G32+G34+G36) | H41: =SUM(C41:G41)
B42: План операций | C42: =SUM(C4+C5+C6+C7+C10+C11+C12+C13+C14+C15+C22+C23+C25+C26+C27+C28+C33+C35+C37) | D42: =SUM(D4+D5+D6+D7+D10+D11+D12+D13+D14+D15+D22+D23+D25+D26+D27+D28+D33+D35+D37) | E42: =SUM(E4+E5+E6+E7+E10+E11+E12+E13+E14+E15+E22+E23+E25+E26+E27+E28+E33+E35+E37) | F42: =SUM(F4+F5+F6+F7+F10+F11+F12+F13+F14+F15+F22+F23+F25+F26+F27+F28+F33+F35+F37) | G42: =SUM(G4+G5+G6+G7+G10+G11+G12+G13+G14+G15+G22+G23+G25+G26+G27+G28+G33+G35+G37) | H42: =SUM(C42:G42)
...

Sheet Февраль
A1: Оториноларингологическое отделение за февраль 2026
B2: С | C2: 46054 | D2: 46062 | E2: 46069 | F2: 46076
B3: По | C3: 46061 | D3: 46068 | E3: 46075 | F3: 46081 | H3: ИТОГ
B4: Аденотомия | C4: 13 | D4: 11 | E4: 18 | F4: 15 | H4: =SUM(C4:G4)
B5: Тонзиллотомия | C5: 6 | D5: 6 | E5: 9 | F5: 8 | H5: =SUM(C5:G5)
B6: Миринготомия план | C6: 3 | D6: 3 | E6: 1 | F6: 2 | H6: =SUM(C6:G6) | S6: ХИРУРГИЧЕСКАЯ РАБОТА ОРГАНИЗАЦИИ (лица старше трудоспособного возраста) 4001
B7: Пластика раковин | C7: 11 | D7: 12 | E7: 12 | F7: 9 | H7: =SUM(C7:G7) | L7: Наименование операции | M7: № строки | N7: Число операций, проведенных в стационаре | R7: из гр.3 направлено материалов на морфол. исследование | S7: Число операций, проведенных в стационаре
B8: ПТА | C8: 3 | D8: 0 | E8: 1 | F8: 3 | H8: =SUM(C8:G8) | N8: всего | O8: из них - детям 0-17 лет включительно | S8: Всего (из гр.3 т.4000)
B9: Миринготомия экстр | C9: 0 | D9: 0 | E9: 0 | F9: 0 | H9: =SUM(C9:G9) | O9: 0-14 лет включи-тельно | P9: из гр.4 в возрасте до 1 года | Q9: 15-17 лет включи-тельно
B10: Полипотомия | C10: 0 | D10: 2 | E10: 0 | F10: 0 | H10: =SUM(C10:G10) | L10: 1 | M10: 2 | N10: 3 | O10: 4 | P10: 5 | Q10: 6 | R10: 28 | S10: 3
B11: Септопластика | C11: 7 | D11: 6 | E11: 5 | F11: 4 | H11: =SUM(C11:G11) | L11: операции на органах уха, горла, носа | M11: 5 | N11: =SUM(N12:N13) | O11: =SUM(O12:O13) | Q11: =SUM(Q12+Q13) | R11: =SUM(R12+R13+H25) | S11: 1
B12: Гайморотомия | C12: 1 | D12: 5 | E12: 3 | F12: 2 | H12: =SUM(C12:G12) | L12: из них - на ухе | M12: 5.1 | N12: =SUM(H6+H9+H16+H22+H26+H24+H32) | O12: =SUM(H6)-Q12 | P12: 0 | Q12: 1 | R12: =SUM(H22+H26) | S12: 1
B13: Тозиллэктомия | C13: 2 | D13: 1 | E13: 3 | F13: 2 | H13: =SUM(C13:G13) | L13: на миндалинах и аденоидах | M13: 5.2 | N13: =SUM(H4+H5+H8+H13) | O13: =SUM(H4+H5)-Q13 | P13: 0 | Q13: 1 | R13: =SUM(H4+H5+H13) | S13: 0
B14: Увулопластика | C14: 0 | D14: 1 | E14: 1 | F14: 0 | H14: =SUM(C14:G14) | L14: операции на органах дыхания | M14: 6 | N14: =SUM(H7+H10+H11+H12+H14+H15+H17+H18+H20+H21+H23+H25+H27+H30+H31+H19+H34+H36+H28+H37) | O14: 0 | P14: 0 | Q14: 4 | R14: =SUM(H10+H12+H14+H27+H28+H37) | S14: 6
B15: Пластика нёба | C15: 0 | D15: 0 | E15: 0 | F15: 0 | H15: =SUM(C15:G15) | L15: из них - на трахее | M15: 6.1 | N15: =SUM(H18) | O15: 0 | P15: 0 | Q15: 0 | R15: 0 | S15: 0
B16: Фурункул НСП | C16: 0 | D16: 2 | E16: 0 | F16: 0 | H16: =SUM(C16:G16) | L16: операции на коже и подкожной клетчатке | M16: 17 | N16: =SUM(H35+H33+H29) | O16: 0 | P16: 0 | Q16: 0 | R16: 0 | S16: 0
B17: Фурункул носа | C17: 1 | D17: 0 | E17: 0 | F17: 1 | H17: =SUM(C17:G17) | L17: Операции лицам пенсионного возраста | N17: 7 | O17: 0 | R17: 0
B18: Трахеостомия | C18: 0 | D18: 0 | E18: 0 | F18: 0 | H18: =SUM(C18:G18) | L18: Всего операций | N18: =N16+N14+N11 | O18: =SUM(O11+O14+O16)-Q14 | Q18: =SUM(Q11+Q14+Q16) | R18: =SUM(R11+R14+R16) | S18: =SUM(S11+S14+S16)
B19: Репозиция костей носа | C19: 0 | D19: 0 | E19: 2 | F19: 1 | H19: =SUM(C19:G19)
B20: Флегмона шеи | C20: 0 | D20: 0 | E20: 0 | F20: 0 | H20: =SUM(C20:G20) | L20: Эндоскопических всего | N20: =H4+H7+H10+H11+H12+H13+H28+H37
B21: Остановка кров | C21: 0 | D21: 0 | E21: 1 | F21: 0 | H21: =SUM(C21:G21)
B22: Рубцы мочки уха | C22: 0 | D22: 0 | E22: 0 | F22: 1 | H22: =SUM(C22:G22)
B23: Синехии нос | C23: 0 | D23: 0 | E23: 0 | F23: 0 | H23: =SUM(C23:G23)
B24: Антромастоидотомия | C24: 0 | D24: 0 | E24: 0 | F24: 0 | H24: =SUM(C24:G24)
B25: Удаление новообр носа | C25: 0 | D25: 0 | E25: 0 | F25: 0 | H25: =SUM(C25:G25)
B26: Удаление новообр уха | C26: 0 | D26: 0 | E26: 1 | F26: 0 | H26: =SUM(C26:G26)
B27: Удаление новообр глотки | C27: 0 | D27: 0 | E27: 0 | F27: 0 | H27: =SUM(C27:G27)
B28: Удаление новообр гортани | C28: 0 | D28: 0 | E28: 0 | F28: 0 | H28: =SUM(C28:G28)
B29: ПХО | C29: 0 | D29: 0 | E29: 0 | F29: 0 | H29: =SUM(C29:G29)
B30: Удаление инородного тела | C30: 0 | D30: 0 | E30: 0 | F30: 0 | H30: =SUM(C30:G30)
B31: Фронтотомия | C31: 0 | D31: 0 | E31: 0 | F31: 0 | H31: =SUM(C31:G31)
B32: Субперостальный абсцесс за ухом | C32: 0 | D32: 0 | E32: 0 | F32: 0 | H32: =SUM(C32:G32)
... B37: Биопсия гортани | C37: 0 | D37: 0 | E37: 0 | F37: 0 | H37: =SUM(C37:G37)
B40: Всего операций | C40: =SUM(C4:C37) | D40: =SUM(D4:D37) | E40: =SUM(E4:E37) | F40: =SUM(F4:F37) | G40: =SUM(G4:G37) | H40: =SUM(C40:G40)
B41: Экстренно операций | C41: =SUM(C8+C9+C16+C17+C18+C19+C20+C21+C24+C29+C30+C31+C32+C34+C36) | D41: =SUM(D8+D9+D16+D17+D18+D19+D20+D21+D24+D29+D30+D31+D32+D34+D36) | E41: =SUM(E8+E9+E16+E17+E18+E19+E20+E21+E24+E29+E30+E31+E32+E34+E36) | F41: =SUM(F8+F9+F16+F17+F18+F19+F20+F21+F24+F29+F30+F31+F32+F34+F36) | G41: =SUM(G8+G9+G16+G17+G18+G19+G20+G21+G24+G29+G30+G31+G32+G34+G36) | H41: =SUM(C41:G41)
B42: План операций | C42: =SUM(C4+C5+C6+C7+C10+C11+C12+C13+C14+C15+C22+C23+C25+C26+C27+C28+C33+C35+C37) | D42: =SUM(D4+D5+D6+D7+D10+D11+D12+D13+D14+D15+D22+D23+D25+D26+D27+D28+D33+D35+D37) | E42: =SUM(E4+E5+E6+E7+E10+E11+E12+E13+E14+E15+E22+E23+E25+E26+E27+E28+E33+E35+E37) | F42: =SUM(F4+F5+F6+F7+F10+F11+F12+F13+F14+F15+F22+F23+F25+F26+F27+F28+F33+F35+F37) | G42: =SUM(G4+G5+G6+G7+G10+G11+G12+G13+G14+G15+G22+G23+G25+G26+G27+G28+G33+G35+G37) | H42: =SUM(C42:G42)
B43: Дети всего | C43: 15 | D43: 13 | E43: 22 | F43: 18 | H43: =SUM(C43:G43)
B44: Взрослые | C44: =C45-C43 | D44: =D45-D43 | E44: =E45-E43 | F44: =F45-F43 | G44: =G45-G43 | H44: =SUM(C44:G44)
B45: Человек | C45: 29 | D45: 29 | E45: 38 | F45: 32 | H45: =SUM(C45:G45)
B47: % Плановых | C47: =C42*100/C40 | D47: =D42*100/D40 | E47: =E42*100/E40 | F47: =F42*100/F40 | G47: =G42*100/G40 | H47: =H42*100/H40
...

Sheet Март
A1: Оториноларингологическое отделение за март 2026
B2: С | C2: 46082 | D2: 46090 | E2: 46097 | F2: 46104 | G2: 46111
B3: По | C3: 46089 | D3: 46096 | E3: 46103 | F3: 46110 | G3: 46112 | H3: ИТОГ
B4: Аденотомия | C4: 15 | D4: 10 | E4: 11 | F4: 13 | G4: 3 | H4: =SUM(C4:G4)
B5: Тонзиллотомия | C5: 7 | D5: 4 | E5: 6 | F5: 9 | G5: 1 | H5: =SUM(C5:G5)
B6: Миринготомия план | H6: =SUM(C6:G6) | S6: ХИРУРГИЧЕСКАЯ РАБОТА ОРГАНИЗАЦИИ (лица старше трудоспособного возраста) 4001
B7: Пластика раковин | C7: 8 | D7: 12 | E7: 10 | F7: 7 | G7: 6 | H7: =SUM(C7:G7) | L7: Наименование операции | M7: № строки | N7: Число операций, проведенных в стационаре | R7: из гр.3 направлено материалов на морфол. исследование | S7: Число операций, проведенных в стационаре
B8: ПТА | C8: 1 | E8: 1 | G8: 1 | H8: =SUM(C8:G8) | N8: всего | O8: из них - детям 0-17 лет включительно | S8: Всего (из гр.3 т.4000)
B9: Миринготомия экстр | C9: 1 | D9: 2 | E9: 2 | F9: 2 | G9: 2 | H9: =SUM(C9:G9) | O9: 0-14 лет включи-тельно | P9: из гр.4 в возрасте до 1 года | Q9: 15-17 лет включи-тельно
B10: Полипотомия | C10: 1 | E10: 1 | G10: 1 | H10: =SUM(C10:G10) | L10: 1 | M10: 2 | N10: 3 | O10: 4 | P10: 5 | Q10: 6 | R10: 28 | S10: 3
B11: Септопластика | C11: 4 | D11: 6 | E11: 2 | F11: 2 | G11: 4 | H11: =SUM(C11:G11) | L11: операции на органах уха, горла, носа | M11: 5 | N11: =SUM(N12:N13) | O11: =SUM(O12:O13) | Q11: =SUM(Q12+Q13) | R11: =SUM(R12+R13+H25) | S11: 2
B12: Гайморотомия | C12: 5 | D12: 3 | G12: 1 | H12: =SUM(C12:G12) | L12: из них - на ухе | M12: 5.1 | N12: =SUM(H6+H9+H16+H22+H26+H24+H32) | O12: 0 | Q12: 1 | R12: =SUM(H22+H26) | S12: 2
B13: Тозиллэктомия | C13: 3 | D13: 2 | F13: 1 | G13: 1 | H13: =SUM(C13:G13) | L13: на миндалинах и аденоидах | M13: 5.2 | N13: =SUM(H4+H5+H8+H13) | O13: =SUM(H4+H5)-Q13 | Q13: 1 | R13: =SUM(H4+H5+H13)
B14: Увулопластика | C14: 1 | H14: =SUM(C14:G14) | L14: операции на органах дыхания | M14: 6 | N14: =SUM(H7+H10+H11+H12+H14+H15+H17+H18+H20+H21+H23+H25+H27+H30+H31+H19+H34+H36+H28+H37) | O14: 0 | Q14: 1 | R14: =SUM(H10+H12+H14+H27+H28+H37) | S14: 8
B15: Пластика нёба | H15: =SUM(C15:G15) | L15: из них - на трахее | M15: 6.1 | N15: =SUM(H18) | O15: 0 | R15: 0
B16: Фурункул НСП | D16: 1 | F16: 1 | G16: 1 | H16: =SUM(C16:G16) | L16: операции на коже и подкожной клетчатке | M16: 17 | N16: =SUM(H35+H33+H29) | O16: 0 | Q16: 0 | R16: 0
B17: Фурункул носа | D17: 1 | F17: 1 | H17: =SUM(C17:G17) | L17: Операции лицам пенсионного возраста | N17: 0 | O17: 0 | R17: 0
B18: Трахеостомия | E18: 1 | H18: =SUM(C18:G18) | L18: Всего операций | N18: =N16+N14+N11 | O18: =SUM(O11+O14+O16)-Q14 | Q18: =SUM(Q11+Q14+Q16) | R18: =SUM(R11+R14+R16) | S18: =SUM(S11+S14+S16)
B19: Репозиция костей носа | C19: 2 | E19: 1 | H19: =SUM(C19:G19)
B20: Флегмона шеи | H20: =SUM(C20:G20) | L20: Эндоскопических всего | N20: =H4+H7+H10+H11+H12+H13+H28+H37
B21: Остановка кров | E21: 1 | F21: 1 | G21: 3 | H21: =SUM(C21:G21)
B22: Рубцы мочки уха | F22: 1 | H22: =SUM(C22:G22)
B23: Синехии нос | H23: =SUM(C23:G23)
B24: Антромастоидотомия | H24: =SUM(C24:G24)
B25: Удаление новообр носа | H25: =SUM(C25:G25)
B26: Удаление новообр уха | E26: 1 | H26: =SUM(C26:G26)
B27: Удаление новообр глотки | F27: 1 | H27: =SUM(C27:G27)
B28: Удаление новообр гортани | E28: 1 | H28: =SUM(C28:G28)
B29: ПХО | H29: =SUM(C29:G29)
B30: Удаление инородного тела | H30: =SUM(C30:G30)
B31: Фронтотомия | H31: =SUM(C31:G31)
B32: Субперостальный абсцесс за ухом | H32: =SUM(C32:G32)
B33: Пластика местными тканями | E33: 1 | F33: 1 | H33: =SUM(C33:G33)
B34: Ревизия п/о полости | H34: =SUM(C34:G34)
B35: Наложение вторичных швов | H35: =SUM(C35:G35)
B36: Заглоточный абсцесс | H36: =SUM(C36:G36)
B37: Биопсия гортани | H37: =SUM(C37:G37)
B40: Всего операций | C40: =SUM(C4:C37) | D40: =SUM(D4:D37) | E40: =SUM(E4:E37) | F40: =SUM(F4:F37) | G40: =SUM(G4:G37) | H40: =SUM(C40:G40)
B41: Экстренно операций | C41: =SUM(C8+C9+C16+C17+C18+C19+C20+C21+C24+C29+C30+C31+C32+C34+C36) | D41: =SUM(D8+D9+D16+D17+D18+D19+D20+D21+D24+D29+D30+D31+D32+D34+D36) | E41: =SUM(E8+E9+E16+E17+E18+E19+E20+E21+E24+E29+E30+E31+E32+E34+E36) | F41: =SUM(F8+F9+F16+F17+F18+F19+F20+F21+F24+F29+F30+F31+F32+F34+F36) | G41: =SUM(G8+G9+G16+G17+G18+G19+G20+G21+G24+G29+G30+G31+G32+G34+G36) | H41: =SUM(C41:G41)
B42: План операций | C42: =SUM(C4+C5+C6+C7+C10+C11+C12+C13+C14+C15+C22+C23+C25+C26+C27+C28+C33+C35+C37) | D42: =SUM(D4+D5+D6+D7+D10+D11+D12+D13+D14+D15+D22+D23+D25+D26+D27+D28+D33+D35+D37) | E42: =SUM(E4+E5+E6+E7+E10+E11+E12+E13+E14+E15+E22+E23+E25+E26+E27+E28+E33+E35+E37) | F42: =SUM(F4+F5+F6+F7+F10+F11+F12+F13+F14+F15+F22+F23+F25+F26+F27+F28+F33+F35+F37) | G42: =SUM(G4+G5+G6+G7+G10+G11+G12+G13+G14+G15+G22+G23+G25+G26+G27+G28+G33+G35+G37) | H42: =SUM(C42:G42)
...

Sheet Апрель
A1: Оториноларингологическое отделение за апрель 2026
B2: С | C2: 46113 | D2: =IF(C3="","",IF(C3+1>EOMONTH($C$2,0),"",C3+1)) | E2: =IF(D3="","",IF(D3+1>EOMONTH($C$2,0),"",D3+1)) | F2: =IF(E3="","",IF(E3+1>EOMONTH($C$2,0),"",E3+1)) | G2: =IF(F3="","",IF(F3+1>EOMONTH($C$2,0),"",F3+1))
B3: По | C3: =IF(C2="","",MIN(C2+7-WEEKDAY(C2,2),EOMONTH($C$2,0))) | D3: =IF(D2="","",MIN(D2+6,EOMONTH($C$2,0))) | E3: =IF(E2="","",MIN(E2+6,EOMONTH($C$2,0))) | F3: =IF(F2="","",MIN(F2+6,EOMONTH($C$2,0))) | G3: =IF(G2="","",MIN(G2+6,EOMONTH($C$2,0))) | H3: ИТОГ
B4: Аденотомия | C4: 6 | D4: 11 | E4: 14 | F4: 9 | G4: 13 | H4: =SUM(C4:G4)
B5: Тонзиллотомия | C5: 5 | D5: 6 | E5: 5 | F5: 5 | G5: 6 | H5: =SUM(C5:G5)
B6: Миринготомия план | C6: 2 | D6: 0 | E6: 2 | F6: 1 | G6: 0 | H6: =SUM(C6:G6) | S6: ХИРУРГИЧЕСКАЯ РАБОТА ОРГАНИЗАЦИИ (лица старше трудоспособного возраста) 4001
B7: Пластика раковин | C7: 4 | D7: 5 | E7: 12 | F7: 14 | G7: 11 | H7: =SUM(C7:G7) | L7: Наименование операции | M7: № строки | N7: Число операций, проведенных в стационаре | R7: из гр.3 направлено материалов на морфол. исследование | S7: Число операций, проведенных в стационаре
B8: ПТА | C8: 1 | D8: 3 | E8: 4 | F8: 4 | G8: 2 | H8: =SUM(C8:G8) | N8: всего | O8: из них - детям 0-17 лет включительно | S8: Всего (из гр.3 т.4000)
B9: Миринготомия экстр | C9: 0 | D9: 0 | E9: 0 | F9: 0 | G9: 0 | H9: =SUM(C9:G9) | O9: 0-14 лет включи-тельно | P9: из гр.4 в возрасте до 1 года | Q9: 15-17 лет включи-тельно
B10: Полипотомия | C10: 1 | D10: 1 | E10: 0 | F10: 0 | G10: 0 | H10: =SUM(C10:G10) | L10: 1 | M10: 2 | N10: 3 | O10: 4 | P10: 5 | Q10: 6 | R10: 28 | S10: 3
B11: Септопластика | C11: 0 | D11: 2 | E11: 4 | F11: 5 | G11: 6 | H11: =SUM(C11:G11) | L11: операции на органах уха, горла, носа | M11: 5 | N11: =SUM(N12:N13) | O11: =SUM(O12:O13) | Q11: =SUM(Q12+Q13) | R11: =SUM(R12+R13+H25) | S11: 7
B12: Гайморотомия | C12: 1 | D12: 1 | E12: 2 | F12: 2 | G12: 2 | H12: =SUM(C12:G12) | L12: из них - на ухе | M12: 5.1 | N12: =SUM(H6+H9+H16+H22+H26+H24+H32) | O12: =SUM(H6)-Q12 | Q12: 0 | R12: =SUM(H22+H26) | S12: 1
B13: Тозиллэктомия | C13: 0 | D13: 2 | E13: 1 | F13: 2 | G13: 1 | H13: =SUM(C13:G13) | L13: на миндалинах и аденоидах | M13: 5.2 | N13: =SUM(H4+H5+H8+H13) | O13: =SUM(H4+H5)-Q13 | Q13: 3 | R13: =SUM(H4+H5+H13) | S13: 1
B14: Увулопластика | C14: 0 | D14: 0 | E14: 0 | F14: 1 | G14: 3 | H14: =SUM(C14:G14) | L14: операции на органах дыхания | M14: 6 | N14: =SUM(H7+H10+H11+H12+H14+H15+H17+H18+H20+H21+H23+H25+H27+H30+H31+H19+H34+H36+H28+H37) | O14: 0 | Q14: 0 | R14: =SUM(H10+H12+H14+H27+H28+H37) | S14: 1
B15: Пластика нёба | C15: 0 | D15: 0 | E15: 0 | F15: 0 | G15: 0 | H15: =SUM(C15:G15) | L15: из них - на трахее | M15: 6.1 | N15: =SUM(H18) | O15: 0 | R15: 0
B16: Фурункул НСП | C16: 1 | D16: 1 | E16: 1 | F16: 0 | G16: 0 | H16: =SUM(C16:G16) | L16: операции на коже и подкожной клетчатке | M16: 17 | N16: =SUM(H35+H33+H29) | O16: 0 | Q16: 0 | R16: 0
B17: Фурункул носа | C17: 0 | D17: 0 | E17: 1 | F17: 1 | G17: 0 | H17: =SUM(C17:G17) | L17: Операции лицам пенсионного возраста | N17: 0 | O17: 0 | R17: 0
B18: Трахеостомия | C18: 0 | D18: 0 | E18: 1 | F18: 0 | G18: 0 | H18: =SUM(C18:G18) | L18: Всего операций | N18: =N16+N14+N11 | O18: =SUM(O11+O14+O16)-Q14 | Q18: =SUM(Q11+Q14+Q16) | R18: =SUM(R11+R14+R16) | S18: =SUM(S11+S14+S16)
B19: Репозиция костей носа | C19: 1 | D19: 0 | E19: 1 | F19: 0 | G19: 1 | H19: =SUM(C19:G19)
B20: Флегмона шеи | C20: 0 | D20: 0 | E20: 0 | F20: 0 | G20: 0 | H20: =SUM(C20:G20) | L20: Эндоскопических всего | N20: =H4+H7+H10+H11+H12+H13+H28+H37
B21: Остановка кров | C21: 0 | D21: 0 | E21: 4 | F21: 3 | G21: 2 | H21: =SUM(C21:G21)
B22: Рубцы мочки уха | C22: 0 | D22: 0 | E22: 0 | F22: 0 | G22: 0 | H22: =SUM(C22:G22)
B23: Синехии нос | C23: 0 | D23: 0 | E23: 0 | F23: 0 | G23: 0 | H23: =SUM(C23:G23)
B24: Антромастоидотомия | C24: 0 | D24: 0 | E24: 0 | F24: 0 | G24: 0 | H24: =SUM(C24:G24)
B25: Удаление новообр носа | C25: 0 | D25: 0 | E25: 0 | F25: 2 | G25: 0 | H25: =SUM(C25:G25)
B26: Удаление новообр уха | C26: 0 | D26: 0 | E26: 0 | F26: 0 | G26: 0 | H26: =SUM(C26:G26)
B27: Удаление новообр глотки | C27: 0 | D27: 0 | E27: 0 | F27: 0 | G27: 0 | H27: =SUM(C27:G27)
B28: Удаление новообр гортани | C28: 0 | D28: 0 | E28: 0 | F28: 0 | G28: 0 | H28: =SUM(C28:G28)
B29: ПХО | C29: 0 | D29: 0 | E29: 0 | F29: 0 | G29: 0 | H29: =SUM(C29:G29)
B30: Удаление инородного тела | C30: 0 | D30: 1 | E30: 2 | F30: 0 | G30: 0 | H30: =SUM(C30:G30)
B31: Фронтотомия | C31: 0 | D31: 0 | E31: 0 | F31: 0 | G31: 0 | H31: =SUM(C31:G31)
B32: Субперостальный абсцесс за ухом | C32: 0 | D32: 0 | E32: 0 | F32: 0 | G32: 0 | H32: =SUM(C32:G32)
... B37: Биопсия гортани | C37: 0 | D37: 0 | E37: 0 | F37: 0 | G37: 0 | H37: =SUM(C37:G37)
B40: Всего операций | C40: =SUM(C4:C37) | D40: =SUM(D4:D37) | E40: =SUM(E4:E37) | F40: =SUM(F4:F37) | G40: =SUM(G4:G37) | H40: =SUM(C40:G40)
B41: Экстренно операций | C41: =SUM(C8+C9+C16+C17+C18+C19+C20+C21+C24+C29+C30+C31+C32+C34+C36) | D41: =SUM(D8+D9+D16+D17+D18+D19+D20+D21+D24+D29+D30+D31+D32+D34+D36) | E41: =SUM(E8+E9+E16+E17+E18+E19+E20+E21+E24+E29+E30+E31+E32+E34+E36) | F41: =SUM(F8+F9+F16+F17+F18+F19+F20+F21+F24+F29+F30+F31+F32+F34+F36) | G41: =SUM(G8+G9+G16+G17+G18+G19+G20+G21+G24+G29+G30+G31+G32+G34+G36) | H41: =SUM(C41:G41)
B42: План операций | C42: =SUM(C4+C5+C6+C7+C10+C11+C12+C13+C14+C15+C22+C23+C25+C26+C27+C28+C33+C35+C37) | D42: =SUM(D4+D5+D6+D7+D10+D11+D12+D13+D14+D15+D22+D23+D25+D26+D27+D28+D33+D35+D37) | E42: =SUM(E4+E5+E6+E7+E10+E11+E12+E13+E14+E15+E22+E23+E25+E26+E27+E28+E33+E35+E37) | F42: =SUM(F4+F5+F6+F7+F10+F11+F12+F13+F14+F15+F22+F23+F25+F26+F27+F28+F33+F35+F37) | G42: =SUM(G4+G5+G6+G7+G10+G11+G12+G13+G14+G15+G22+G23+G25+G26+G27+G28+G33+G35+G37) | H42: =SUM(C42:G42)
B43: Дети всего | C43: 6 | D43: 13 | E43: 17 | F43: 9 | G43: 13 | H43: =SUM(C43:G43)
B44: Взрослые | C44: =C45-C43 | D44: =D45-D43 | E44: =E45-E43 | F44: =F45-F43 | G44: =G45-G43 | H44: =SUM(C44:G44)
B45: Человек | C45: 15 | D45: 24 | E45: 38 | F45: 34 | G45: 29 | H45: =SUM(C45:G45)
B47: % Плановых | C47: =C42*100/C40 | D47: =D42*100/D40 | E47: =E42*100/E40 | F47: =F42*100/F40 | G47: =G42*100/G40 | H47: =H42*100/H40
...

Sheet Май
A1: Оториноларингологическое отделение за май 2026
B2: С | C2: 46143 | D2: =IF(C3="","",IF(C3+1>EOMONTH($C$2,0),"",C3+1)) | E2: =IF(D3="","",IF(D3+1>EOMONTH($C$2,0),"",D3+1)) | F2: =IF(E3="","",IF(E3+1>EOMONTH($C$2,0),"",E3+1)) | G2: =IF(F3="","",IF(F3+1>EOMONTH($C$2,0),"",F3+1))
B3: По | C3: =IF(C2="","",MIN(C2+7-WEEKDAY(C2,2),EOMONTH($C$2,0))) | D3: =IF(D2="","",MIN(D2+6,EOMONTH($C$2,0))) | E3: =IF(E2="","",MIN(E2+6,EOMONTH($C$2,0))) | F3: =IF(F2="","",MIN(F2+6,EOMONTH($C$2,0))) | G3: =IF(G2="","",MIN(G2+6,EOMONTH($C$2,0))) | H3: ИТОГ
B4: Аденотомия | D4: 21 | E4: 9 | F4: 14 | G4: 11 | H4: =SUM(C4:G4)
B5: Тонзиллотомия | D5: 8 | E5: 6 | F5: 7 | G5: 5 | H5: =SUM(C5:G5)
B6: Миринготомия план | D6: 3 | H6: =SUM(C6:G6) | S6: ХИРУРГИЧЕСКАЯ РАБОТА ОРГАНИЗАЦИИ (лица старше трудоспособного возраста) 4001
B7: Пластика раковин | D7: 8 | E7: 11 | F7: 8 | G7: 12 | H7: =SUM(C7:G7) | L7: Наименование операции | M7: № строки | N7: Число операций, проведенных в стационаре | R7: из гр.3 направлено материалов на морфол. исследование | S7: Число операций, проведенных в стационаре
B8: ПТА | D8: 1 | E8: 3 | F8: 1 | G8: 4 | H8: =SUM(C8:G8) | N8: всего | O8: из них - детям 0-17 лет включительно | S8: Всего (из гр.3 т.4000)
B9: Миринготомия экстр | F9: 2 | G9: 2 | H9: =SUM(C9:G9) | O9: 0-14 лет включи-тельно | P9: из гр.4 в возрасте до 1 года | Q9: 15-17 лет включи-тельно
B10: Полипотомия | E10: 1 | G10: 2 | H10: =SUM(C10:G10) | L10: 1 | M10: 2 | N10: 3 | O10: 4 | P10: 5 | Q10: 6 | R10: 28 | S10: 3
B11: Септопластика | D11: 6 | E11: 4 | F11: 5 | G11: 6 | H11: =SUM(C11:G11) | L11: операции на органах уха, горла, носа | M11: 5 | N11: =SUM(N12:N13) | O11: =SUM(O12:O13) | Q11: =SUM(Q12+Q13) | R11: =SUM(R12+R13+H25)
B12: Гайморотомия | D12: 1 | F12: 2 | G12: 3 | H12: =SUM(C12:G12) | L12: из них - на ухе | M12: 5.1 | N12: =SUM(H6+H9+H16+H22+H26+H24+H32) | O12: =SUM(H6)-Q12 | Q12: 0 | R12: =SUM(H22+H26)
B13: Тозиллэктомия | D13: 1 | E13: 1 | F13: 3 | H13: =SUM(C13:G13) | L13: на миндалинах и аденоидах | M13: 5.2 | N13: =SUM(H4+H5+H8+H13) | O13: =SUM(H4+H5)-Q13 | Q13: 0 | R13: =SUM(H4+H5+H13)
B14: Увулопластика | E14: 1 | H14: =SUM(C14:G14) | L14: операции на органах дыхания | M14: 6 | N14: =SUM(H7+H10+H11+H12+H14+H15+H17+H18+H20+H21+H23+H25+H27+H30+H31+H19+H34+H36+H28+H37) | O14: 0 | Q14: 0 | R14: =SUM(H10+H12+H14+H27+H28+H37)
B15: Пластика нёба | H15: =SUM(C15:G15) | L15: из них - на трахее | M15: 6.1 | N15: =SUM(H18) | O15: 0 | R15: 0
B16: Фурункул НСП | D16: 2 | G16: 1 | H16: =SUM(C16:G16) | L16: операции на коже и подкожной клетчатке | M16: 17 | N16: =SUM(H35+H33+H29) | O16: 0 | Q16: 0 | R16: 0
B17: Фурункул носа | E17: 1 | F17: 1 | G17: 1 | H17: =SUM(C17:G17) | L17: Операции лицам пенсионного возраста | N17: 0 | O17: 0 | R17: 0
B18: Трахеостомия | G18: 1 | H18: =SUM(C18:G18) | L18: Всего операций | N18: =N16+N14+N11 | O18: =SUM(O11+O14+O16)-Q14 | Q18: =SUM(Q11+Q14+Q16) | R18: =SUM(R11+R14+R16) | S18: =SUM(S11+S14+S16)
B19: Репозиция костей носа | F19: 1 | H19: =SUM(C19:G19)
B20: Флегмона шеи | H20: =SUM(C20:G20) | L20: Эндоскопических всего | N20: =H4+H7+H10+H11+H12+H13+H28+H37
B21: Остановка кров | E21: 1 | F21: 1 | H21: =SUM(C21:G21)
B22: Рубцы мочки уха | H22: =SUM(C22:G22)
B23: Синехии нос | G23: 1 | H23: =SUM(C23:G23)
B24: Антромастоидотомия | H24: =SUM(C24:G24)
B25: Удаление новообр носа | H25: =SUM(C25:G25)
B26: Удаление новообр уха | D26: 1 | E26: 1 | H26: =SUM(C26:G26)
B27: Удаление новообр глотки | D27: 1 | E27: 1 | H27: =SUM(C27:G27)
B28: Удаление новообр гортани | H28: =SUM(C28:G28)
B29: ПХО | H29: =SUM(C29:G29)
B30: Удаление инородного тела | D30: 1 | H30: =SUM(C30:G30)
B31: Фронтотомия | H31: =SUM(C31:G31)
B32: Субперостальный абсцесс за ухом | H32: =SUM(C32:G32)
B33: Пластика местными тканями | D33: 1 | E33: 1 | H33: =SUM(C33:G33)
B34: Ревизия п/о полости | H34: =SUM(C34:G34)
B35: Наложение вторичных швов | H35: =SUM(C35:G35)
B36: Заглоточный абсцесс | H36: =SUM(C36:G36)
B37: Биопсия гортани | E37: 1 | F37: 2 | G37: 1 | H37: =SUM(C37:G37)
B40: Всего операций | C40: =SUM(C4:C37) | D40: =SUM(D4:D37) | E40: =SUM(E4:E37) | F40: =SUM(F4:F37) | G40: =SUM(G4:G37) | H40: =SUM(C40:G40)
B41: Экстренно операций | C41: =SUM(C8+C9+C16+C17+C18+C19+C20+C21+C24+C29+C30+C31+C32+C34+C36) | D41: =SUM(D8+D9+D16+D17+D18+D19+D20+D21+D24+D29+D30+D31+D32+D34+D36) | E41: =SUM(E8+E9+E16+E17+E18+E19+E20+E21+E24+E29+E30+E31+E32+E34+E36) | F41: =SUM(F8+F9+F16+F17+F18+F19+F20+F21+F24+F29+F30+F31+F32+F34+F36) | G41: =SUM(G8+G9+G16+G17+G18+G19+G20+G21+G24+G29+G30+G31+G32+G34+G36) | H41: =SUM(C41:G41)
B42: План операций | C42: =SUM(C4+C5+C6+C7+C10+C11+C12+C13+C14+C15+C22+C23+C25+C26+C27+C28+C33+C35+C37) | D42: =SUM(D4+D5+D6+D7+D10+D11+D12+D13+D14+D15+D22+D23+D25+D26+D27+D28+D33+D35+D37) | E42: =SUM(E4+E5+E6+E7+E10+E11+E12+E13+E14+E15+E22+E23+E25+E26+E27+E28+E33+E35+E37) | F42: =SUM(F4+F5+F6+F7+F10+F11+F12+F13+F14+F15+F22+F23+F25+F26+F27+F28+F33+F35+F37) | G42: =SUM(G4+G5+G6+G7+G10+G11+G12+G13+G14+G15+G22+G23+G25+G26+G27+G28+G33+G35+G37) | H42: =SUM(C42:G42)
...

Sheet Июнь
A1: Оториноларингологическое отделение за июнь 2026
B2: С | C2: 46174 | D2: =IF(C3="","",IF(C3+1>EOMONTH($C$2,0),"",C3+1)) | E2: =IF(D3="","",IF(D3+1>EOMONTH($C$2,0),"",D3+1)) | F2: =IF(E3="","",IF(E3+1>EOMONTH($C$2,0),"",E3+1)) | G2: =IF(F3="","",IF(F3+1>EOMONTH($C$2,0),"",F3+1))
B3: По | C3: =IF(C2="","",MIN(C2+7-WEEKDAY(C2,2),EOMONTH($C$2,0))) | D3: =IF(D2="","",MIN(D2+6,EOMONTH($C$2,0))) | E3: =IF(E2="","",MIN(E2+6,EOMONTH($C$2,0))) | F3: =IF(F2="","",MIN(F2+6,EOMONTH($C$2,0))) | G3: =IF(G2="","",MIN(G2+6,EOMONTH($C$2,0))) | H3: ИТОГ
B4: Аденотомия | H4: =SUM(C4:G4)
B5: Тонзиллотомия | H5: =SUM(C5:G5)
B6: Миринготомия план | H6: =SUM(C6:G6) | S6: ХИРУРГИЧЕСКАЯ РАБОТА ОРГАНИЗАЦИИ (лица старше трудоспособного возраста) 4001
B7: Пластика раковин | H7: =SUM(C7:G7) | L7: Наименование операции | M7: № строки | N7: Число операций, проведенных в стационаре | R7: из гр.3 направлено материалов на морфол. исследование | S7: Число операций, проведенных в стационаре
B8: ПТА | H8: =SUM(C8:G8) | N8: всего | O8: из них - детям 0-17 лет включительно | S8: Всего (из гр.3 т.4000)
B9: Миринготомия экстр | H9: =SUM(C9:G9) | O9: 0-14 лет включи-тельно | P9: из гр.4 в возрасте до 1 года | Q9: 15-17 лет включи-тельно
B10: Полипотомия | H10: =SUM(C10:G10) | L10: 1 | M10: 2 | N10: 3 | O10: 4 | P10: 5 | Q10: 6 | R10: 28 | S10: 3
B11: Септопластика | H11: =SUM(C11:G11) | L11: операции на органах уха, горла, носа | M11: 5 | N11: =SUM(N12:N13) | O11: =SUM(O12:O13) | Q11: =SUM(Q12+Q13) | R11: =SUM(R12+R13+H25)
B12: Гайморотомия | H12: =SUM(C12:G12) | L12: из них - на ухе | M12: 5.1 | N12: =SUM(H6+H9+H16+H22+H26+H24+H32) | O12: =SUM(H6)-Q12 | Q12: 0 | R12: =SUM(H22+H26)
B13: Тозиллэктомия | H13: =SUM(C13:G13) | L13: на миндалинах и аденоидах | M13: 5.2 | N13: =SUM(H4+H5+H8+H13) | O13: =SUM(H4+H5)-Q13 | Q13: 0 | R13: =SUM(H4+H5+H13)
B14: Увулопластика | H14: =SUM(C14:G14) | L14: операции на органах дыхания | M14: 6 | N14: =SUM(H7+H10+H11+H12+H14+H15+H17+H18+H20+H21+H23+H25+H27+H30+H31+H19+H34+H36+H28+H37) | O14: 0 | Q14: 0 | R14: =SUM(H10+H12+H14+H27+H28+H37)
B15: Пластика нёба | H15: =SUM(C15:G15) | L15: из них - на трахее | M15: 6.1 | N15: =SUM(H18) | O15: 0 | R15: 0
B16: Фурункул НСП | H16: =SUM(C16:G16) | L16: операции на коже и подкожной клетчатке | M16: 17 | N16: =SUM(H35+H33+H29) | O16: 0 | Q16: 0 | R16: 0
B17: Фурункул носа | H17: =SUM(C17:G17) | L17: Операции лицам пенсионного возраста | N17: 0 | O17: 0 | R17: 0
B18: Трахеостомия | H18: =SUM(C18:G18) | L18: Всего операций | N18: =N16+N14+N11 | O18: =SUM(O11+O14+O16)-Q14 | Q18: =SUM(Q11+Q14+Q16) | R18: =SUM(R11+R14+R16) | S18: =SUM(S11+S14+S16)
B19: Репозиция костей носа | H19: =SUM(C19:G19)
B20: Флегмона шеи | H20: =SUM(C20:G20) | L20: Эндоскопических всего | N20: =H4+H7+H10+H11+H12+H13+H28+H37
B21: Остановка кров | H21: =SUM(C21:G21)
B22: Рубцы мочки уха | H22: =SUM(C22:G22)
B23: Синехии нос | H23: =SUM(C23:G23)
B24: Антромастоидотомия | H24: =SUM(C24:G24)
B25: Удаление новообр носа | H25: =SUM(C25:G25)
B26: Удаление новообр уха | H26: =SUM(C26:G26)
B27: Удаление новообр глотки | H27: =SUM(C27:G27)
B28: Удаление новообр гортани | H28: =SUM(C28:G28)
B29: ПХО | H29: =SUM(C29:G29)
B30: Удаление инородного тела | H30: =SUM(C30:G30)
B31: Фронтотомия | H31: =SUM(C31:G31)
B32: Субперостальный абсцесс за ухом | H32: =SUM(C32:G32)
... B37: Биопсия гортани | H37: =SUM(C37:G37)
B40: Всего операций | C40: =SUM(C4:C37) | D40: =SUM(D4:D37) | E40: =SUM(E4:E37) | F40: =SUM(F4:F37) | G40: =SUM(G4:G37) | H40: =SUM(C40:G40)
B41: Экстренно операций | C41: =SUM(C8+C9+C16+C17+C18+C19+C20+C21+C24+C29+C30+C31+C32+C34+C36) | D41: =SUM(D8+D9+D16+D17+D18+D19+D20+D21+D24+D29+D30+D31+D32+D34+D36) | E41: =SUM(E8+E9+E16+E17+E18+E19+E20+E21+E24+E29+E30+E31+E32+E34+E36) | F41: =SUM(F8+F9+F16+F17+F18+F19+F20+F21+F24+F29+F30+F31+F32+F34+F36) | G41: =SUM(G8+G9+G16+G17+G18+G19+G20+G21+G24+G29+G30+G31+G32+G34+G36) | H41: =SUM(C41:G41)
B42: План операций | C42: =SUM(C4+C5+C6+C7+C10+C11+C12+C13+C14+C15+C22+C23+C25+C26+C27+C28+C33+C35+C37) | D42: =SUM(D4+D5+D6+D7+D10+D11+D12+D13+D14+D15+D22+D23+D25+D26+D27+D28+D33+D35+D37) | E42: =SUM(E4+E5+E6+E7+E10+E11+E12+E13+E14+E15+E22+E23+E25+E26+E27+E28+E33+E35+E37) | F42: =SUM(F4+F5+F6+F7+F10+F11+F12+F13+F14+F15+F22+F23+F25+F26+F27+F28+F33+F35+F37) | G42: =SUM(G4+G5+G6+G7+G10+G11+G12+G13+G14+G15+G22+G23+G25+G26+G27+G28+G33+G35+G37) | H42: =SUM(C42:G42)
B43: Дети всего | H43: =SUM(C43:G43)
B44: Взрослые | C44: =C45-C43 | D44: =D45-D43 | E44: =E45-E43 | F44: =F45-F43 | G44: =G45-G43 | H44: =SUM(C44:G44)
B45: Человек | H45: =SUM(C45:G45)
B47: % Плановых | C47: =C42*100/C40 | D47: =D42*100/D40 | E47: =E42*100/E40 | F47: =F42*100/F40 | G47: =G42*100/G40 | H47: =H42*100/H40
...

Sheet Июль
A1: Оториноларингологическое отделение за июль 2026
B2: С | C2: 46204 | D2: =IF(C3="","",IF(C3+1>EOMONTH($C$2,0),"",C3+1))
B3: По | C3: =IF(C2="","",MIN(C2+7-WEEKDAY(C2,2),EOMONTH($C$2,0))) | D3: =IF(D2="","",MIN(D2+6,EOMONTH($C$2,0))) | H3: ИТОГ
B4: Аденотомия | H4: =SUM(C4:G4)
B5: Тонзиллотомия | H5: =SUM(C5:G5)
B6: Миринготомия план | H6: =SUM(C6:G6) | S6: ХИРУРГИЧЕСКАЯ РАБОТА ОРГАНИЗАЦИИ (лица старше трудоспособного возраста) 4001
B7: Пластика раковин | H7: =SUM(C7:G7) | L7: Наименование операции | M7: № строки | N7: Число операций, проведенных в стационаре | R7: из гр.3 направлено материалов на морфол. исследование | S7: Число операций, проведенных в стационаре
B8: ПТА | H8: =SUM(C8:G8) | N8: всего | O8: из них - детям 0-17 лет включительно | S8: Всего (из гр.3 т.4000)
B9: Миринготомия экстр | H9: =SUM(C9:G9) | O9: 0-14 лет включи-тельно | P9: из гр.4 в возрасте до 1 года | Q9: 15-17 лет включи-тельно
B10: Полипотомия | H10: =SUM(C10:G10) | L10: 1 | M10: 2 | N10: 3 | O10: 4 | P10: 5 | Q10: 6 | R10: 28 | S10: 3
B11: Септопластика | H11: =SUM(C11:G11) | L11: операции на органах уха, горла, носа | M11: 5 | N11: =SUM(N12:N13) | O11: =SUM(O12:O13) | Q11: =SUM(Q12+Q13) | R11: =SUM(R12+R13+H25)
B12: Гайморотомия | H12: =SUM(C12:G12) | L12: из них - на ухе | M12: 5.1 | N12: =SUM(H6+H9+H16+H22+H26+H24+H32) | O12: =SUM(H6)-Q12 | Q12: 0 | R12: =SUM(H22+H26)
B13: Тозиллэктомия | H13: =SUM(C13:G13) | L13: на миндалинах и аденоидах | M13: 5.2 | N13: =SUM(H4+H5+H8+H13) | O13: =SUM(H4+H5)-Q13 | Q13: 0 | R13: =SUM(H4+H5+H13)
B14: Увулопластика | H14: =SUM(C14:G14) | L14: операции на органах дыхания | M14: 6 | N14: =SUM(H7+H10+H11+H12+H14+H15+H17+H18+H20+H21+H23+H25+H27+H30+H31+H19+H34+H36+H28+H37) | O14: 0 | Q14: 0 | R14: =SUM(H10+H12+H14+H27+H28+H37)
B15: Пластика нёба | H15: =SUM(C15:G15) | L15: из них - на трахее | M15: 6.1 | N15: =SUM(H18) | O15: 0 | R15: 0
B16: Фурункул НСП | H16: =SUM(C16:G16) | L16: операции на коже и подкожной клетчатке | M16: 17 | N16: =SUM(H35+H33+H29) | O16: 0 | Q16: 0 | R16: 0
B17: Фурункул носа | H17: =SUM(C17:G17) | L17: Операции лицам пенсионного возраста | N17: 0 | O17: 0 | R17: 0
B18: Трахеостомия | H18: =SUM(C18:G18) | L18: Всего операций | N18: =N16+N14+N11 | O18: =SUM(O11+O14+O16)-Q14 | Q18: =SUM(Q11+Q14+Q16) | R18: =SUM(R11+R14+R16) | S18: =SUM(S11+S14+S16)
B19: Репозиция костей носа | H19: =SUM(C19:G19)
B20: Флегмона шеи | H20: =SUM(C20:G20) | L20: Эндоскопических всего | N20: =H4+H7+H10+H11+H12+H13+H28+H37
B21: Остановка кров | H21: =SUM(C21:G21)
B22: Рубцы мочки уха | H22: =SUM(C22:G22)
B23: Синехии нос | H23: =SUM(C23:G23)
B24: Антромастоидотомия | H24: =SUM(C24:G24)
B25: Удаление новообр носа | H25: =SUM(C25:G25)
B26: Удаление новообр уха | H26: =SUM(C26:G26)
B27: Удаление новообр глотки | H27: =SUM(C27:G27)
B28: Удаление новообр гортани | H28: =SUM(C28:G28)
B29: ПХО | H29: =SUM(C29:G29)
B30: Удаление инородного тела | H30: =SUM(C30:G30)
B31: Фронтотомия | H31: =SUM(C31:G31)
B32: Субперостальный абсцесс за ухом | H32: =SUM(C32:G32)
... B37: Биопсия гортани | H37: =SUM(C37:G37)
B40: Всего операций | C40: =SUM(C4:C37) | D40: =SUM(D4:D37) | E40: =SUM(E4:E37) | F40: =SUM(F4:F37) | G40: =SUM(G4:G37) | H40: =SUM(C40:G40)
B41: Экстренно операций | C41: =SUM(C8+C9+C16+C17+C18+C19+C20+C21+C24+C29+C30+C31+C32+C34+C36) | D41: =SUM(D8+D9+D16+D17+D18+D19+D20+D21+D24+D29+D30+D31+D32+D34+D36) | E41: =SUM(E8+E9+E16+E17+E18+E19+E20+E21+E24+E29+E30+E31+E32+E34+E36) | F41: =SUM(F8+F9+F16+F17+F18+F19+F20+F21+F24+F29+F30+F31+F32+F34+F36) | G41: =SUM(G8+G9+G16+G17+G18+G19+G20+G21+G24+G29+G30+G31+G32+G34+G36) | H41: =SUM(C41:G41)
B42: План операций | C42: =SUM(C4+C5+C6+C7+C10+C11+C12+C13+C14+C15+C22+C23+C25+C26+C27+C28+C33+C35+C37) | D42: =SUM(D4+D5+D6+D7+D10+D11+D12+D13+D14+D15+D22+D23+D25+D26+D27+D28+D33+D35+D37) | E42: =SUM(E4+E5+E6+E7+E10+E11+E12+E13+E14+E15+E22+E23+E25+E26+E27+E28+E33+E35+E37) | F42: =SUM(F4+F5+F6+F7+F10+F11+F12+F13+F14+F15+F22+F23+F25+F26+F27+F28+F33+F35+F37) | G42: =SUM(G4+G5+G6+G7+G10+G11+G12+G13+G14+G15+G22+G23+G25+G26+G27+G28+G33+G35+G37) | H42: =SUM(C42:G42)
B43: Дети всего | H43: =SUM(C43:G43)
B44: Взрослые | C44: =C45-C43 | D44: =D45-D43 | E44: =E45-E43 | F44: =F45-F43 | G44: =G45-G43 | H44: =SUM(C44:G44)
B45: Человек | H45: =SUM(C45:G45)
B47: % Плановых | C47: =C42*100/C40 | D47: =D42*100/D40 | E47: =E42*100/E40 | F47: =F42*100/F40 | G47: =G42*100/G40 | H47: =H42*100/H40
...

Sheet Август
A1: Оториноларингологическое отделение за август 2026
B2: С | C2: 46235 | D2: =IF(C3="","",IF(C3+1>EOMONTH($C$2,0),"",C3+1))
B3: По | C3: =IF(C2="","",MIN(C2+7-WEEKDAY(C2,2),EOMONTH($C$2,0))) | D3: =IF(D2="","",MIN(D2+6,EOMONTH($C$2,0))) | H3: ИТОГ
B4: Аденотомия | H4: =SUM(C4:G4)
B5: Тонзиллотомия | H5: =SUM(C5:G5)
B6: Миринготомия план | H6: =SUM(C6:G6) | S6: ХИРУРГИЧЕСКАЯ РАБОТА ОРГАНИЗАЦИИ (лица старше трудоспособного возраста) 4001
B7: Пластика раковин | H7: =SUM(C7:G7) | L7: Наименование операции | M7: № строки | N7: Число операций, проведенных в стационаре | R7: из гр.3 направлено материалов на морфол. исследование | S7: Число операций, проведенных в стационаре
B8: ПТА | H8: =SUM(C8:G8) | N8: всего | O8: из них - детям 0-17 лет включительно | S8: Всего (из гр.3 т.4000)
B9: Миринготомия экстр | H9: =SUM(C9:G9) | O9: 0-14 лет включи-тельно | P9: из гр.4 в возрасте до 1 года | Q9: 15-17 лет включи-тельно
B10: Полипотомия | H10: =SUM(C10:G10) | L10: 1 | M10: 2 | N10: 3 | O10: 4 | P10: 5 | Q10: 6 | R10: 28 | S10: 3
B11: Септопластика | H11: =SUM(C11:G11) | L11: операции на органах уха, горла, носа | M11: 5 | N11: =SUM(N12:N13) | O11: =SUM(O12:O13) | Q11: =SUM(Q12+Q13) | R11: =SUM(R12+R13+H25)
B12: Гайморотомия | H12: =SUM(C12:G12) | L12: из них - на ухе | M12: 5.1 | N12: =SUM(H6+H9+H16+H22+H26+H24+H32) | O12: =SUM(H6)-Q12 | Q12: 0 | R12: =SUM(H22+H26)
B13: Тозиллэктомия | H13: =SUM(C13:G13) | L13: на миндалинах и аденоидах | M13: 5.2 | N13: =SUM(H4+H5+H8+H13) | O13: =SUM(H4+H5)-Q13 | Q13: 0 | R13: =SUM(H4+H5+H13)
B14: Увулопластика | H14: =SUM(C14:G14) | L14: операции на органах дыхания | M14: 6 | N14: =SUM(H7+H10+H11+H12+H14+H15+H17+H18+H20+H21+H23+H25+H27+H30+H31+H19+H34+H36+H28+H37) | O14: 0 | Q14: 0 | R14: =SUM(H10+H12+H14+H27+H28+H37)
B15: Пластика нёба | H15: =SUM(C15:G15) | L15: из них - на трахее | M15: 6.1 | N15: =SUM(H18) | O15: 0 | R15: 0
B16: Фурункул НСП | H16: =SUM(C16:G16) | L16: операции на коже и подкожной клетчатке | M16: 17 | N16: =SUM(H35+H33+H29) | O16: 0 | Q16: 0 | R16: 0
B17: Фурункул носа | H17: =SUM(C17:G17) | L17: Операции лицам пенсионного возраста | N17: 0 | O17: 0 | R17: 0
B18: Трахеостомия | H18: =SUM(C18:G18) | L18: Всего операций | N18: =N16+N14+N11 | O18: =SUM(O11+O14+O16)-Q14 | Q18: =SUM(Q11+Q14+Q16) | R18: =SUM(R11+R14+R16) | S18: =SUM(S11+S14+S16)
B19: Репозиция костей носа | H19: =SUM(C19:G19)
B20: Флегмона шеи | H20: =SUM(C20:G20) | L20: Эндоскопических всего | N20: =H4+H7+H10+H11+H12+H13+H28+H37
B21: Остановка кров | H21: =SUM(C21:G21)
B22: Рубцы мочки уха | H22: =SUM(C22:G22)
B23: Синехии нос | H23: =SUM(C23:G23)
B24: Антромастоидотомия | H24: =SUM(C24:G24)
B25: Удаление новообр носа | H25: =SUM(C25:G25)
B26: Удаление новообр уха | H26: =SUM(C26:G26)
B27: Удаление новообр глотки | H27: =SUM(C27:G27)
B28: Удаление новообр гортани | H28: =SUM(C28:G28)
B29: ПХО | H29: =SUM(C29:G29)
B30: Удаление инородного тела | H30: =SUM(C30:G30)
B31: Фронтотомия | H31: =SUM(C31:G31)
B32: Субперостальный абсцесс за ухом | H32: =SUM(C32:G32)
... B37: Биопсия гортани | H37: =SUM(C37:G37)
B40: Всего операций | C40: =SUM(C4:C37) | D40: =SUM(D4:D37) | E40: =SUM(E4:E37) | F40: =SUM(F4:F37) | G40: =SUM(G4:G37) | H40: =SUM(C40:G40)
B41: Экстренно операций | C41: =SUM(C8+C9+C16+C17+C18+C19+C20+C21+C24+C29+C30+C31+C32+C34+C36) | D41: =SUM(D8+D9+D16+D17+D18+D19+D20+D21+D24+D29+D30+D31+D32+D34+D36) | E41: =SUM(E8+E9+E16+E17+E18+E19+E20+E21+E24+E29+E30+E31+E32+E34+E36) | F41: =SUM(F8+F9+F16+F17+F18+F19+F20+F21+F24+F29+F30+F31+F32+F34+F36) | G41: =SUM(G8+G9+G16+G17+G18+G19+G20+G21+G24+G29+G30+G31+G32+G34+G36) | H41: =SUM(C41:G41)
B42: План операций | C42: =SUM(C4+C5+C6+C7+C10+C11+C12+C13+C14+C15+C22+C23+C25+C26+C27+C28+C33+C35+C37) | D42: =SUM(D4+D5+D6+D7+D10+D11+D12+D13+D14+D15+D22+D23+D25+D26+D27+D28+D33+D35+D37) | E42: =SUM(E4+E5+E6+E7+E10+E11+E12+E13+E14+E15+E22+E23+E25+E26+E27+E28+E33+E35+E37) | F42: =SUM(F4+F5+F6+F7+F10+F11+F12+F13+F14+F15+F22+F23+F25+F26+F27+F28+F33+F35+F37) | G42: =SUM(G4+G5+G6+G7+G10+G11+G12+G13+G14+G15+G22+G23+G25+G26+G27+G28+G33+G35+G37) | H42: =SUM(C42:G42)
B43: Дети всего | H43: =SUM(C43:G43)
B44: Взрослые | C44: =C45-C43 | D44: =D45-D43 | E44: =E45-E43 | F44: =F45-F43 | G44: =G45-G43 | H44: =SUM(C44:G44)
B45: Человек | H45: =SUM(C45:G45)
B47: % Плановых | C47: =C42*100/C40 | D47: =D42*100/D40 | E47: =E42*100/E40 | F47: =F42*100/F40 | G47: =G42*100/G40 | H47: =H42*100/H40
...

Sheet Сентябрь
A1: Оториноларингологическое отделение за сентябрь 2026
B2: С | C2: 46266 | D2: =IF(C3="","",IF(C3+1>EOMONTH($C$2,0),"",C3+1))
B3: По | C3: =IF(C2="","",MIN(C2+7-WEEKDAY(C2,2),EOMONTH($C$2,0))) | D3: =IF(D2="","",MIN(D2+6,EOMONTH($C$2,0))) | H3: ИТОГ
B4: Аденотомия | H4: =SUM(C4:G4)
B5: Тонзиллотомия | H5: =SUM(C5:G5)
B6: Миринготомия план | H6: =SUM(C6:G6) | S6: ХИРУРГИЧЕСКАЯ РАБОТА ОРГАНИЗАЦИИ (лица старше трудоспособного возраста) 4001
B7: Пластика раковин | H7: =SUM(C7:G7) | L7: Наименование операции | M7: № строки | N7: Число операций, проведенных в стационаре | R7: из гр.3 направлено материалов на морфол. исследование | S7: Число операций, проведенных в стационаре
B8: ПТА | H8: =SUM(C8:G8) | N8: всего | O8: из них - детям 0-17 лет включительно | S8: Всего (из гр.3 т.4000)
B9: Миринготомия экстр | H9: =SUM(C9:G9) | O9: 0-14 лет включи-тельно | P9: из гр.4 в возрасте до 1 года | Q9: 15-17 лет включи-тельно
B10: Полипотомия | H10: =SUM(C10:G10) | L10: 1 | M10: 2 | N10: 3 | O10: 4 | P10: 5 | Q10: 6 | R10: 28 | S10: 3
B11: Септопластика | H11: =SUM(C11:G11) | L11: операции на органах уха, горла, носа | M11: 5 | N11: =SUM(N12:N13) | O11: =SUM(O12:O13) | Q11: =SUM(Q12+Q13) | R11: =SUM(R12+R13+H25)
B12: Гайморотомия | H12: =SUM(C12:G12) | L12: из них - на ухе | M12: 5.1 | N12: =SUM(H6+H9+H16+H22+H26+H24+H32) | O12: =SUM(H6)-Q12 | Q12: 0 | R12: =SUM(H22+H26)
B13: Тозиллэктомия | H13: =SUM(C13:G13) | L13: на миндалинах и аденоидах | M13: 5.2 | N13: =SUM(H4+H5+H8+H13) | O13: =SUM(H4+H5)-Q13 | Q13: 0 | R13: =SUM(H4+H5+H13)
B14: Увулопластика | H14: =SUM(C14:G14) | L14: операции на органах дыхания | M14: 6 | N14: =SUM(H7+H10+H11+H12+H14+H15+H17+H18+H20+H21+H23+H25+H27+H30+H31+H19+H34+H36+H28+H37) | O14: 0 | Q14: 0 | R14: =SUM(H10+H12+H14+H27+H28+H37)
B15: Пластика нёба | H15: =SUM(C15:G15) | L15: из них - на трахее | M15: 6.1 | N15: =SUM(H18) | O15: 0 | R15: 0
B16: Фурункул НСП | H16: =SUM(C16:G16) | L16: операции на коже и подкожной клетчатке | M16: 17 | N16: =SUM(H35+H33+H29) | O16: 0 | Q16: 0 | R16: 0
B17: Фурункул носа | H17: =SUM(C17:G17) | L17: Операции лицам пенсионного возраста | N17: 0 | O17: 0 | R17: 0
B18: Трахеостомия | H18: =SUM(C18:G18) | L18: Всего операций | N18: =N16+N14+N11 | O18: =SUM(O11+O14+O16)-Q14 | Q18: =SUM(Q11+Q14+Q16) | R18: =SUM(R11+R14+R16) | S18: =SUM(S11+S14+S16)
B19: Репозиция костей носа | H19: =SUM(C19:G19)
B20: Флегмона шеи | H20: =SUM(C20:G20) | L20: Эндоскопических всего | N20: =H4+H7+H10+H11+H12+H13+H28+H37
B21: Остановка кров | H21: =SUM(C21:G21)
B22: Рубцы мочки уха | H22: =SUM(C22:G22)
B23: Синехии нос | H23: =SUM(C23:G23)
B24: Антромастоидотомия | H24: =SUM(C24:G24)
B25: Удаление новообр носа | H25: =SUM(C25:G25)
B26: Удаление новообр уха | H26: =SUM(C26:G26)
B27: Удаление новообр глотки | H27: =SUM(C27:G27)
B28: Удаление новообр гортани | H28: =SUM(C28:G28)
B29: ПХО | H29: =SUM(C29:G29)
B30: Удаление инородного тела | H30: =SUM(C30:G30)
B31: Фронтотомия | H31: =SUM(C31:G31)
B32: Субперостальный абсцесс за ухом | H32: =SUM(C32:G32)
... B37: Биопсия гортани | H37: =SUM(C37:G37)
B40: Всего операций | C40: =SUM(C4:C37) | D40: =SUM(D4:D37) | E40: =SUM(E4:E37) | F40: =SUM(F4:F37) | G40: =SUM(G4:G37) | H40: =SUM(C40:G40)
B41: Экстренно операций | C41: =SUM(C8+C9+C16+C17+C18+C19+C20+C21+C24+C29+C30+C31+C32+C34+C36) | D41: =SUM(D8+D9+D16+D17+D18+D19+D20+D21+D24+D29+D30+D31+D32+D34+D36) | E41: =SUM(E8+E9+E16+E17+E18+E19+E20+E21+E24+E29+E30+E31+E32+E34+E36) | F41: =SUM(F8+F9+F16+F17+F18+F19+F20+F21+F24+F29+F30+F31+F32+F34+F36) | G41: =SUM(G8+G9+G16+G17+G18+G19+G20+G21+G24+G29+G30+G31+G32+G34+G36) | H41: =SUM(C41:G41)
B42: План операций | C42: =SUM(C4+C5+C6+C7+C10+C11+C12+C13+C14+C15+C22+C23+C25+C26+C27+C28+C33+C35+C37) | D42: =SUM(D4+D5+D6+D7+D10+D11+D12+D13+D14+D15+D22+D23+D25+D26+D27+D28+D33+D35+D37) | E42: =SUM(E4+E5+E6+E7+E10+E11+E12+E13+E14+E15+E22+E23+E25+E26+E27+E28+E33+E35+E37) | F42: =SUM(F4+F5+F6+F7+F10+F11+F12+F13+F14+F15+F22+F23+F25+F26+F27+F28+F33+F35+F37) | G42: =SUM(G4+G5+G6+G7+G10+G11+G12+G13+G14+G15+G22+G23+G25+G26+G27+G28+G33+G35+G37) | H42: =SUM(C42:G42)
B43: Дети всего | H43: =SUM(C43:G43)
B44: Взрослые | C44: =C45-C43 | D44: =D45-D43 | E44: =E45-E43 | F44: =F45-F43 | G44: =G45-G43 | H44: =SUM(C44:G44)
B45: Человек | H45: =SUM(C45:G45)
B47: % Плановых | C47: =C42*100/C40 | D47: =D42*100/D40 | E47: =E42*100/E40 | F47: =F42*100/F40 | G47: =G42*100/G40 | H47: =H42*100/H40
...

Sheet Октябрь 
A1: Оториноларингологическое отделение за октябрь 2026
B2: С | C2: 46296 | D2: =IF(C3="","",IF(C3+1>EOMONTH($C$2,0),"",C3+1))
B3: По | C3: =IF(C2="","",MIN(C2+7-WEEKDAY(C2,2),EOMONTH($C$2,0))) | D3: =IF(D2="","",MIN(D2+6,EOMONTH($C$2,0))) | H3: ИТОГ
B4: Аденотомия | H4: =SUM(C4:G4)
B5: Тонзиллотомия | H5: =SUM(C5:G5)
B6: Миринготомия план | H6: =SUM(C6:G6) | S6: ХИРУРГИЧЕСКАЯ РАБОТА ОРГАНИЗАЦИИ (лица старше трудоспособного возраста) 4001
B7: Пластика раковин | H7: =SUM(C7:G7) | L7: Наименование операции | M7: № строки | N7: Число операций, проведенных в стационаре | R7: из гр.3 направлено материалов на морфол. исследование | S7: Число операций, проведенных в стационаре
B8: ПТА | H8: =SUM(C8:G8) | N8: всего | O8: из них - детям 0-17 лет включительно | S8: Всего (из гр.3 т.4000)
B9: Миринготомия экстр | H9: =SUM(C9:G9) | O9: 0-14 лет включи-тельно | P9: из гр.4 в возрасте до 1 года | Q9: 15-17 лет включи-тельно
B10: Полипотомия | H10: =SUM(C10:G10) | L10: 1 | M10: 2 | N10: 3 | O10: 4 | P10: 5 | Q10: 6 | R10: 28 | S10: 3
B11: Септопластика | H11: =SUM(C11:G11) | L11: операции на органах уха, горла, носа | M11: 5 | N11: =SUM(N12:N13) | O11: =SUM(O12:O13) | Q11: =SUM(Q12+Q13) | R11: =SUM(R12+R13+H25)
B12: Гайморотомия | H12: =SUM(C12:G12) | L12: из них - на ухе | M12: 5.1 | N12: =SUM(H6+H9+H16+H22+H26+H24+H32) | O12: =SUM(H6)-Q12 | Q12: 0 | R12: =SUM(H22+H26)
B13: Тозиллэктомия | H13: =SUM(C13:G13) | L13: на миндалинах и аденоидах | M13: 5.2 | N13: =SUM(H4+H5+H8+H13) | O13: =SUM(H4+H5)-Q13 | Q13: 0 | R13: =SUM(H4+H5+H13)
B14: Увулопластика | H14: =SUM(C14:G14) | L14: операции на органах дыхания | M14: 6 | N14: =SUM(H7+H10+H11+H12+H14+H15+H17+H18+H20+H21+H23+H25+H27+H30+H31+H19+H34+H36+H28+H37) | O14: 0 | Q14: 0 | R14: =SUM(H10+H12+H14+H27+H28+H37)
B15: Пластика нёба | H15: =SUM(C15:G15) | L15: из них - на трахее | M15: 6.1 | N15: =SUM(H18) | O15: 0 | R15: 0
B16: Фурункул НСП | H16: =SUM(C16:G16) | L16: операции на коже и подкожной клетчатке | M16: 17 | N16: =SUM(H35+H33+H29) | O16: 0 | Q16: 0 | R16: 0
B17: Фурункул носа | H17: =SUM(C17:G17) | L17: Операции лицам пенсионного возраста | N17: 0 | O17: 0 | R17: 0
B18: Трахеостомия | H18: =SUM(C18:G18) | L18: Всего операций | N18: =N16+N14+N11 | O18: =SUM(O11+O14+O16)-Q14 | Q18: =SUM(Q11+Q14+Q16) | R18: =SUM(R11+R14+R16) | S18: =SUM(S11+S14+S16)
B19: Репозиция костей носа | H19: =SUM(C19:G19)
B20: Флегмона шеи | H20: =SUM(C20:G20) | L20: Эндоскопических всего | N20: =H4+H7+H10+H11+H12+H13+H28+H37
B21: Остановка кров | H21: =SUM(C21:G21)
B22: Рубцы мочки уха | H22: =SUM(C22:G22)
B23: Синехии нос | H23: =SUM(C23:G23)
B24: Антромастоидотомия | H24: =SUM(C24:G24)
B25: Удаление новообр носа | H25: =SUM(C25:G25)
B26: Удаление новообр уха | H26: =SUM(C26:G26)
B27: Удаление новообр глотки | H27: =SUM(C27:G27)
B28: Удаление новообр гортани | H28: =SUM(C28:G28)
B29: ПХО | H29: =SUM(C29:G29)
B30: Удаление инородного тела | H30: =SUM(C30:G30)
B31: Фронтотомия | H31: =SUM(C31:G31)
B32: Субперостальный абсцесс за ухом | H32: =SUM(C32:G32)
... B37: Биопсия гортани | H37: =SUM(C37:G37)
B40: Всего операций | C40: =SUM(C4:C37) | D40: =SUM(D4:D37) | E40: =SUM(E4:E37) | F40: =SUM(F4:F37) | G40: =SUM(G4:G37) | H40: =SUM(C40:G40)
B41: Экстренно операций | C41: =SUM(C8+C9+C16+C17+C18+C19+C20+C21+C24+C29+C30+C31+C32+C34+C36) | D41: =SUM(D8+D9+D16+D17+D18+D19+D20+D21+D24+D29+D30+D31+D32+D34+D36) | E41: =SUM(E8+E9+E16+E17+E18+E19+E20+E21+E24+E29+E30+E31+E32+E34+E36) | F41: =SUM(F8+F9+F16+F17+F18+F19+F20+F21+F24+F29+F30+F31+F32+F34+F36) | G41: =SUM(G8+G9+G16+G17+G18+G19+G20+G21+G24+G29+G30+G31+G32+G34+G36) | H41: =SUM(C41:G41)
B42: План операций | C42: =SUM(C4+C5+C6+C7+C10+C11+C12+C13+C14+C15+C22+C23+C25+C26+C27+C28+C33+C35+C37) | D42: =SUM(D4+D5+D6+D7+D10+D11+D12+D13+D14+D15+D22+D23+D25+D26+D27+D28+D33+D35+D37) | E42: =SUM(E4+E5+E6+E7+E10+E11+E12+E13+E14+E15+E22+E23+E25+E26+E27+E28+E33+E35+E37) | F42: =SUM(F4+F5+F6+F7+F10+F11+F12+F13+F14+F15+F22+F23+F25+F26+F27+F28+F33+F35+F37) | G42: =SUM(G4+G5+G6+G7+G10+G11+G12+G13+G14+G15+G22+G23+G25+G26+G27+G28+G33+G35+G37) | H42: =SUM(C42:G42)
B43: Дети всего | H43: =SUM(C43:G43)
B44: Взрослые | C44: =C45-C43 | D44: =D45-D43 | E44: =E45-E43 | F44: =F45-F43 | G44: =G45-G43 | H44: =SUM(C44:G44)
B45: Человек | H45: =SUM(C45:G45)
B47: % Плановых | C47: =C42*100/C40 | D47: =D42*100/D40 | E47: =E42*100/E40 | F47: =F42*100/F40 | G47: =G42*100/G40 | H47: =H42*100/H40
...

Sheet Ноябрь
A1: Оториноларингологическое отделение за ноябрь 2026
B2: С | C2: 46327 | D2: =IF(C3="","",IF(C3+1>EOMONTH($C$2,0),"",C3+1))
B3: По | C3: =IF(C2="","",MIN(C2+7-WEEKDAY(C2,2),EOMONTH($C$2,0))) | D3: =IF(D2="","",MIN(D2+6,EOMONTH($C$2,0))) | H3: ИТОГ
B4: Аденотомия | H4: =SUM(C4:G4)
B5: Тонзиллотомия | H5: =SUM(C5:G5)
B6: Миринготомия план | H6: =SUM(C6:G6) | S6: ХИРУРГИЧЕСКАЯ РАБОТА ОРГАНИЗАЦИИ (лица старше трудоспособного возраста) 4001
B7: Пластика раковин | H7: =SUM(C7:G7) | L7: Наименование операции | M7: № строки | N7: Число операций, проведенных в стационаре | R7: из гр.3 направлено материалов на морфол. исследование | S7: Число операций, проведенных в стационаре
B8: ПТА | H8: =SUM(C8:G8) | N8: всего | O8: из них - детям 0-17 лет включительно | S8: Всего (из гр.3 т.4000)
B9: Миринготомия экстр | H9: =SUM(C9:G9) | O9: 0-14 лет включи-тельно | P9: из гр.4 в возрасте до 1 года | Q9: 15-17 лет включи-тельно
B10: Полипотомия | H10: =SUM(C10:G10) | L10: 1 | M10: 2 | N10: 3 | O10: 4 | P10: 5 | Q10: 6 | R10: 28 | S10: 3
B11: Септопластика | H11: =SUM(C11:G11) | L11: операции на органах уха, горла, носа | M11: 5 | N11: =SUM(N12:N13) | O11: =SUM(O12:O13) | Q11: =SUM(Q12+Q13) | R11: =SUM(R12+R13+H25)
B12: Гайморотомия | H12: =SUM(C12:G12) | L12: из них - на ухе | M12: 5.1 | N12: =SUM(H6+H9+H16+H22+H26+H24+H32) | O12: =SUM(H6)-Q12 | Q12: 0 | R12: =SUM(H22+H26)
B13: Тозиллэктомия | H13: =SUM(C13:G13) | L13: на миндалинах и аденоидах | M13: 5.2 | N13: =SUM(H4+H5+H8+H13) | O13: =SUM(H4+H5)-Q13 | Q13: 0 | R13: =SUM(H4+H5+H13)
B14: Увулопластика | H14: =SUM(C14:G14) | L14: операции на органах дыхания | M14: 6 | N14: =SUM(H7+H10+H11+H12+H14+H15+H17+H18+H20+H21+H23+H25+H27+H30+H31+H19+H34+H36+H28+H37) | O14: 0 | Q14: 0 | R14: =SUM(H10+H12+H14+H27+H28+H37)
B15: Пластика нёба | H15: =SUM(C15:G15) | L15: из них - на трахее | M15: 6.1 | N15: =SUM(H18) | O15: 0 | R15: 0
B16: Фурункул НСП | H16: =SUM(C16:G16) | L16: операции на коже и подкожной клетчатке | M16: 17 | N16: =SUM(H35+H33+H29) | O16: 0 | Q16: 0 | R16: 0
B17: Фурункул носа | H17: =SUM(C17:G17) | L17: Операции лицам пенсионного возраста | N17: 0 | O17: 0 | R17: 0
B18: Трахеостомия | H18: =SUM(C18:G18) | L18: Всего операций | N18: =N16+N14+N11 | O18: =SUM(O11+O14+O16)-Q14 | Q18: =SUM(Q11+Q14+Q16) | R18: =SUM(R11+R14+R16) | S18: =SUM(S11+S14+S16)
B19: Репозиция костей носа | H19: =SUM(C19:G19)
B20: Флегмона шеи | H20: =SUM(C20:G20) | L20: Эндоскопических всего | N20: =H4+H7+H10+H11+H12+H13+H28+H37
B21: Остановка кров | H21: =SUM(C21:G21)
B22: Рубцы мочки уха | H22: =SUM(C22:G22)
B23: Синехии нос | H23: =SUM(C23:G23)
B24: Антромастоидотомия | H24: =SUM(C24:G24)
B25: Удаление новообр носа | H25: =SUM(C25:G25)
B26: Удаление новообр уха | H26: =SUM(C26:G26)
B27: Удаление новообр глотки | H27: =SUM(C27:G27)
B28: Удаление новообр гортани | H28: =SUM(C28:G28)
B29: ПХО | H29: =SUM(C29:G29)
B30: Удаление инородного тела | H30: =SUM(C30:G30)
B31: Фронтотомия | H31: =SUM(C31:G31)
B32: Субперостальный абсцесс за ухом | H32: =SUM(C32:G32)
... B37: Биопсия гортани | H37: =SUM(C37:G37)
B40: Всего операций | C40: =SUM(C4:C37) | D40: =SUM(D4:D37) | E40: =SUM(E4:E37) | F40: =SUM(F4:F37) | G40: =SUM(G4:G37) | H40: =SUM(C40:G40)
B41: Экстренно операций | C41: =SUM(C8+C9+C16+C17+C18+C19+C20+C21+C24+C29+C30+C31+C32+C34+C36) | D41: =SUM(D8+D9+D16+D17+D18+D19+D20+D21+D24+D29+D30+D31+D32+D34+D36) | E41: =SUM(E8+E9+E16+E17+E18+E19+E20+E21+E24+E29+E30+E31+E32+E34+E36) | F41: =SUM(F8+F9+F16+F17+F18+F19+F20+F21+F24+F29+F30+F31+F32+F34+F36) | G41: =SUM(G8+G9+G16+G17+G18+G19+G20+G21+G24+G29+G30+G31+G32+G34+G36) | H41: =SUM(C41:G41)
B42: План операций | C42: =SUM(C4+C5+C6+C7+C10+C11+C12+C13+C14+C15+C22+C23+C25+C26+C27+C28+C33+C35+C37) | D42: =SUM(D4+D5+D6+D7+D10+D11+D12+D13+D14+D15+D22+D23+D25+D26+D27+D28+D33+D35+D37) | E42: =SUM(E4+E5+E6+E7+E10+E11+E12+E13+E14+E15+E22+E23+E25+E26+E27+E28+E33+E35+E37) | F42: =SUM(F4+F5+F6+F7+F10+F11+F12+F13+F14+F15+F22+F23+F25+F26+F27+F28+F33+F35+F37) | G42: =SUM(G4+G5+G6+G7+G10+G11+G12+G13+G14+G15+G22+G23+G25+G26+G27+G28+G33+G35+G37) | H42: =SUM(C42:G42)
B43: Дети всего | H43: =SUM(C43:G43)
B44: Взрослые | C44: =C45-C43 | D44: =D45-D43 | E44: =E45-E43 | F44: =F45-F43 | G44: =G45-G43 | H44: =SUM(C44:G44)
B45: Человек | H45: =SUM(C45:G45)
B47: % Плановых | C47: =C42*100/C40 | D47: =D42*100/D40 | E47: =E42*100/E40 | F47: =F42*100/F40 | G47: =G42*100/G40 | H47: =H42*100/H40
...

Sheet Декабрь
A1: Оториноларингологическое отделение за декабрь 2026
B2: С | C2: 46357 | D2: =IF(C3="","",IF(C3+1>EOMONTH($C$2,0),"",C3+1))
B3: По | C3: =IF(C2="","",MIN(C2+7-WEEKDAY(C2,2),EOMONTH($C$2,0))) | D3: =IF(D2="","",MIN(D2+6,EOMONTH($C$2,0))) | H3: ИТОГ
B4: Аденотомия | H4: =SUM(C4:G4)
B5: Тонзиллотомия | H5: =SUM(C5:G5)
B6: Миринготомия план | H6: =SUM(C6:G6) | S6: ХИРУРГИЧЕСКАЯ РАБОТА ОРГАНИЗАЦИИ (лица старше трудоспособного возраста) 4001
B7: Пластика раковин | H7: =SUM(C7:G7) | L7: Наименование операции | M7: № строки | N7: Число операций, проведенных в стационаре | R7: из гр.3 направлено материалов на морфол. исследование | S7: Число операций, проведенных в стационаре
B8: ПТА | H8: =SUM(C8:G8) | N8: всего | O8: из них - детям 0-17 лет включительно | S8: Всего (из гр.3 т.4000)
B9: Миринготомия экстр | H9: =SUM(C9:G9) | O9: 0-14 лет включи-тельно | P9: из гр.4 в возрасте до 1 года | Q9: 15-17 лет включи-тельно
B10: Полипотомия | H10: =SUM(C10:G10) | L10: 1 | M10: 2 | N10: 3 | O10: 4 | P10: 5 | Q10: 6 | R10: 28 | S10: 3
B11: Септопластика | H11: =SUM(C11:G11) | L11: операции на органах уха, горла, носа | M11: 5 | N11: =SUM(N12:N13) | O11: =SUM(O12:O13) | Q11: =SUM(Q12+Q13) | R11: =SUM(R12+R13+H25)
B12: Гайморотомия | H12: =SUM(C12:G12) | L12: из них - на ухе | M12: 5.1 | N12: =SUM(H6+H9+H16+H22+H26+H24+H32) | O12: =SUM(H6)-Q12 | Q12: 0 | R12: =SUM(H22+H26)
B13: Тозиллэктомия | H13: =SUM(C13:G13) | L13: на миндалинах и аденоидах | M13: 5.2 | N13: =SUM(H4+H5+H8+H13) | O13: =SUM(H4+H5)-Q13 | Q13: 0 | R13: =SUM(H4+H5+H13)
B14: Увулопластика | H14: =SUM(C14:G14) | L14: операции на органах дыхания | M14: 6 | N14: =SUM(H7+H10+H11+H12+H14+H15+H17+H18+H20+H21+H23+H25+H27+H30+H31+H19+H34+H36+H28+H37) | O14: 0 | Q14: 0 | R14: =SUM(H10+H12+H14+H27+H28+H37)
B15: Пластика нёба | H15: =SUM(C15:G15) | L15: из них - на трахее | M15: 6.1 | N15: =SUM(H18) | O15: 0 | R15: 0
B16: Фурункул НСП | H16: =SUM(C16:G16) | L16: операции на коже и подкожной клетчатке | M16: 17 | N16: =SUM(H35+H33+H29) | O16: 0 | Q16: 0 | R16: 0
B17: Фурункул носа | H17: =SUM(C17:G17) | L17: Операции лицам пенсионного возраста | N17: 0 | O17: 0 | R17: 0
B18: Трахеостомия | H18: =SUM(C18:G18) | L18: Всего операций | N18: =N16+N14+N11 | O18: =SUM(O11+O14+O16)-Q14 | Q18: =SUM(Q11+Q14+Q16) | R18: =SUM(R11+R14+R16) | S18: =SUM(S11+S14+S16)
B19: Репозиция костей носа | H19: =SUM(C19:G19)
B20: Флегмона шеи | H20: =SUM(C20:G20) | L20: Эндоскопических всего | N20: =H4+H7+H10+H11+H12+H13+H28+H37
B21: Остановка кров | H21: =SUM(C21:G21)
B22: Рубцы мочки уха | H22: =SUM(C22:G22)
B23: Синехии нос | H23: =SUM(C23:G23)
B24: Антромастоидотомия | H24: =SUM(C24:G24)
B25: Удаление новообр носа | H25: =SUM(C25:G25)
B26: Удаление новообр уха | H26: =SUM(C26:G26)
B27: Удаление новообр глотки | H27: =SUM(C27:G27)
B28: Удаление новообр гортани | H28: =SUM(C28:G28)
B29: ПХО | H29: =SUM(C29:G29)
B30: Удаление инородного тела | H30: =SUM(C30:G30)
B31: Фронтотомия | H31: =SUM(C31:G31)
B32: Субперостальный абсцесс за ухом | H32: =SUM(C32:G32)
... B37: Биопсия гортани | H37: =SUM(C37:G37)
B40: Всего операций | C40: =SUM(C4:C37) | D40: =SUM(D4:D37) | E40: =SUM(E4:E37) | F40: =SUM(F4:F37) | G40: =SUM(G4:G37) | H40: =SUM(C40:G40)
B41: Экстренно операций | C41: =SUM(C8+C9+C16+C17+C18+C19+C20+C21+C24+C29+C30+C31+C32+C34+C36) | D41: =SUM(D8+D9+D16+D17+D18+D19+D20+D21+D24+D29+D30+D31+D32+D34+D36) | E41: =SUM(E8+E9+E16+E17+E18+E19+E20+E21+E24+E29+E30+E31+E32+E34+E36) | F41: =SUM(F8+F9+F16+F17+F18+F19+F20+F21+F24+F29+F30+F31+F32+F34+F36) | G41: =SUM(G8+G9+G16+G17+G18+G19+G20+G21+G24+G29+G30+G31+G32+G34+G36) | H41: =SUM(C41:G41)
B42: План операций | C42: =SUM(C4+C5+C6+C7+C10+C11+C12+C13+C14+C15+C22+C23+C25+C26+C27+C28+C33+C35+C37) | D42: =SUM(D4+D5+D6+D7+D10+D11+D12+D13+D14+D15+D22+D23+D25+D26+D27+D28+D33+D35+D37) | E42: =SUM(E4+E5+E6+E7+E10+E11+E12+E13+E14+E15+E22+E23+E25+E26+E27+E28+E33+E35+E37) | F42: =SUM(F4+F5+F6+F7+F10+F11+F12+F13+F14+F15+F22+F23+F25+F26+F27+F28+F33+F35+F37) | G42: =SUM(G4+G5+G6+G7+G10+G11+G12+G13+G14+G15+G22+G23+G25+G26+G27+G28+G33+G35+G37) | H42: =SUM(C42:G42)
B43: Дети всего | H43: =SUM(C43:G43)
B44: Взрослые | C44: =C45-C43 | D44: =D45-D43 | E44: =E45-E43 | F44: =F45-F43 | G44: =G45-G43 | H44: =SUM(C44:G44)
B45: Человек | H45: =SUM(C45:G45)
B47: % Плановых | C47: =C42*100/C40 | D47: =D42*100/D40 | E47: =E42*100/E40 | F47: =F42*100/F40 | G47: =G42*100/G40 | H47: =H42*100/H40
...

Sheet ОБЩАЯ
A1: Оториноларингологическое отделение ОБЩАЯ 2025
C3: ИТОГ
B4: Аденотомия | C4: =SUM(Январь!H4+Февраль!H4+Март!H4+Апрель!H4+Май!H4+Июнь!H4+Июль!H4+Август!H4+Сентябрь!H4+'Октябрь '!H4+Ноябрь!H4+Декабрь!H4)
B5: Тонзиллотомия | C5: =SUM(Январь!H5+Февраль!H5+Март!H5+Апрель!H5+Май!H5+Июнь!H5+Июль!H5+Август!H5+Сентябрь!H5+'Октябрь '!H5+Ноябрь!H5+Декабрь!H5)
B6: Миринготомия план | C6: =SUM(Январь!H6+Февраль!H6+Март!H6+Апрель!H6+Май!H6+Июнь!H6+Июль!H6+Август!H6+Сентябрь!H6+'Октябрь '!H6+Ноябрь!H6+Декабрь!H6) | N6: ХИРУРГИЧЕСКАЯ РАБОТА ОРГАНИЗАЦИИ (лица старше трудоспособного возраста) 4001
B7: Пластика раковин | C7: =SUM(Январь!H7+Февраль!H7+Март!H7+Апрель!H7+Май!H7+Июнь!H7+Июль!H7+Август!H7+Сентябрь!H7+'Октябрь '!H7+Ноябрь!H7+Декабрь!H7) | G7: Наименование операции | H7: № строки | I7: Число операций, проведенных в стационаре | M7: из гр.3 направлено материалов на морфол. исследование | N7: Число операций, проведенных в стационаре
B8: ПТА | C8: =SUM(Январь!H8+Февраль!H8+Март!H8+Апрель!H8+Май!H8+Июнь!H8+Июль!H8+Август!H8+Сентябрь!H8+'Октябрь '!H8+Ноябрь!H8+Декабрь!H8) | I8: всего | J8: из них - детям 0-17 лет включительно | N8: Всего (из гр.3 т.4000)
B9: Миринготомия экстр | C9: =SUM(Январь!H9+Февраль!H9+Март!H9+Апрель!H9+Май!H9+Июнь!H9+Июль!H9+Август!H9+Сентябрь!H9+'Октябрь '!H9+Ноябрь!H9+Декабрь!H9) | J9: 0-14 лет включи-тельно | K9: из гр.4 в возрасте до 1 года | L9: 15-17 лет включи-тельно
B10: Полипотомия | C10: =SUM(Январь!H10+Февраль!H10+Март!H10+Апрель!H10+Май!H10+Июнь!H10+Июль!H10+Август!H10+Сентябрь!H10+'Октябрь '!H10+Ноябрь!H10+Декабрь!H10) | G10: 1 | H10: 2 | I10: 3 | J10: 4 | K10: 5 | L10: 6 | M10: 28 | N10: 3
